Workbook
Name referenciaTD: #REF!
Name referenciaTD: #REF!
Name referenciaTD: #REF!
Name referenciaTD: #REF!
Name referenciaTD: #REF!
Name referenciaTD: #REF!
Name referenciaTD: #REF!
Name referenciaTD: #REF!
Name referenciaTD: #REF!
Name referenciaTD: #REF!
Name referenciaTD: #REF!
Name referenciaTD: #REF!
Name referenciaTD: #REF!
Name referenciaTD: #REF!
Name referenciaTD: #REF!
Name referenciaTD: #REF!
Name SegmentaciónDeDatos_centroCosto: #N/A
Name SegmentaciónDeDatos_Comprobante: #N/A
Name SegmentaciónDeDatos_Comprobante1: #N/A
Name SegmentaciónDeDatos_DateHierarchy: #N/A
Name SegmentaciónDeDatos_fecha__año: #N/A
Name SegmentaciónDeDatos_Mes__mmm: #N/A
Name SegmentaciónDeDatos_Mes__mmm1: #N/A
Name SegmentaciónDeDatos_Unidad: #N/A

Sheet Selectores
I2: Mes del reporte | N2: Que no esté seleccionado :
F3: Cuando esté el 3000 seleccionar | N3: 01 ING TI IDIEM FACT
N4: 05 PROV ING TI IDIEM FACT
N5: 06 REV PROV ING TI IDIEM FACT
N6: 04 TRAS RECLASIFICA TI
N8: Ojo si hay reclasificaciones, también hay que sacarlo, pero ojalá no saque otras reclasificaciones que no hay que sacar
A28: Meses año actual para el Salesforce

Sheet Indicaciones SGC
A1: Indicaciones
A3: 0. Actualizar
A4: 1. Actualizar hoja "Selectores"
A5: 2. Al cambiar año actualizar la fecha en hoja "Año_reporte", debe ser el último día del año.
A6: 3. Seguir pasos de hoja "Indicaciones GCO"

Sheet Indicaciones GCO
A1: Indicaciones
A3: 0. Solo limitarse a seguir estos pasos.
A4: 1. Actualizar hoja "Reporte Salesforce". Esta hoja se encuentra vinculada una consulta de Salesforce y se actualiza cada 4 horas partiendo a las 7:20.
A5: 2. En hoja "Cuadratura" verificar que todas las celdas marcadas en amarillo sean 0.
A6: 3. En hoja "BBDD Gráficos" verificar que todas las celdas marcadas en amarillo sean 0.

Sheet Reporte Salesforce
A1: Rut Empresa | B1: Nombre de la cuenta | C1: Nombre de la oportunidad | D1: Etapa | E1: Monto | F1: Contador de cuotas | G1: Fecha de cierre del Negocio | H1: Unidad | I1: División | J1: Sección | K1: Presupuesto sincronizado | L1: Fecha de Pago | M1: Traspaso interno
A2: 760779946 | B2: Sociedad LEM Laboratorios & Asistencia Técnica Limitada | C2: PR.DHI.SHI.2026-0777 | D2: Cerrada ganada | E2: 2018731 | F2: 1 | G2: 46213 | H2: 1815 UFMA- Laboratorio de Áridos | I2: DHI | J2: SHI - Sección Hormigones Ingeniería | K2: Análisis físico-mecánicos y químicos en muestra(s) de árido(s). | L2: 46213 | M2: FALSO
A3: 761097792 | B3: MELÓN S.A. | C3: PR.DHI.SHI.2026-0905 | D3: Cerrada ganada | E3: 3935811 | F3: 1 | G3: 46211 | H3: 1815 UFMA- Laboratorio de Áridos | I3: DHI | J3: SHI - Sección Hormigones Ingeniería | K3: Caracterización de áridos planta Osorno M-4055231 | L3: 46211 | M3: FALSO
A4: 969369109 | B4: INDUSTRIA DE TUBOS Y PREFABRICADOS DE HORMIGON BUDNIK S A | C4: PR.DHI.SHI.2026-0564 | D4: Cerrada ganada | E4: 304723 | F4: 1 | G4: 46209 | H4: 1815 UFMA- Laboratorio de Áridos | I4: DHI | J4: SHI - Sección Hormigones Ingeniería | K4: Análisis físico-mecánico a muestra(s) de árido(s) | L4: 46209 | M4: FALSO
A5: 761097792 | B5: MELÓN S.A. | C5: PR.DHI.SHI.2026-0876 | D5: Cerrada ganada | E5: 3826399 | F5: 1 | G5: 46205 | H5: 1815 UFMA- Laboratorio de Áridos | I5: DHI | J5: SHI - Sección Hormigones Ingeniería | K5: Caracterización de áridos planta Villarrica M-4055191 | L5: 46205 | M5: FALSO
A6: 761097792 | B6: MELÓN S.A. | C6: PR.DHI.SHI.2026-0875 | D6: Cerrada ganada | E6: 5056711 | F6: 1 | G6: 46205 | H6: 1815 UFMA- Laboratorio de Áridos | I6: DHI | J6: SHI - Sección Hormigones Ingeniería | K6: Caracterización de áridos planta Temuco M-4055190 | L6: 46205 | M6: FALSO
A7: 760779946 | B7: Sociedad LEM Laboratorios & Asistencia Técnica Limitada | C7: PR.DHI.SHI.2026-0519 | D7: Cerrada ganada | E7: 1217226 | F7: 1 | G7: 46198 | H7: 1815 UFMA- Laboratorio de Áridos | I7: DHI | J7: SHI - Sección Hormigones Ingeniería | K7: Análisis físico-mecánicos y químicos en muestra(s) de árido(s). | L7: 46198 | M7: FALSO
A8: 760779946 | B8: Sociedad LEM Laboratorios & Asistencia Técnica Limitada | C8: PR.DHI.SHI.2026-0520 | D8: Cerrada ganada | E8: 1216826 | F8: 1 | G8: 46198 | H8: 1815 UFMA- Laboratorio de Áridos | I8: DHI | J8: SHI - Sección Hormigones Ingeniería | K8: Análisis físico-mecánicos y químicos en muestra(s) de árido(s). | L8: 46198 | M8: FALSO
A9: 761097792 | B9: MELÓN S.A. | C9: PR.DHI.SHI.2026-0850 | D9: Cerrada ganada | E9: 1309996 | F9: 1 | G9: 46197 | H9: 1815 UFMA- Laboratorio de Áridos | I9: DHI | J9: SHI - Sección Hormigones Ingeniería | K9: Caracterización de árido planta Osorno - Vicat Pozo Cachillahue M-28579 | L9: 46197 | M9: FALSO
A10: 761097792 | B10: MELÓN S.A. | C10: PR.DHI.SHI.2026-0826 | D10: Cerrada ganada | E10: 4055745 | F10: 1 | G10: 46191 | H10: 1815 UFMA- Laboratorio de Áridos | I10: DHI | J10: SHI - Sección Hormigones Ingeniería | K10: Caracterización de áridos planta Castro M-4055393 | L10: 46191 | M10: FALSO
A11: 761097792 | B11: MELÓN S.A. | C11: PR.DHI.SHI.2026-0827 | D11: Cerrada ganada | E11: 4065449 | F11: 1 | G11: 46191 | H11: 1815 UFMA- Laboratorio de Áridos | I11: DHI | J11: SHI - Sección Hormigones Ingeniería | K11: Caracterización de áridos planta Chadmo M-4055320 | L11: 46191 | M11: FALSO
A12: 78465110K | B12: MELÓN ÁRIDOS LIMITADA | C12: PR.DHI.SHI.2026-0823 | D12: Cerrada ganada | E12: 906344 | F12: 1 | G12: 46191 | H12: 1815 UFMA- Laboratorio de Áridos | I12: DHI | J12: SHI - Sección Hormigones Ingeniería | K12: Control de áridos mensual planta PSB Junio M-4068150 | L12: 46191 | M12: FALSO
A13: 78465110K | B13: MELÓN ÁRIDOS LIMITADA | C13: PR.DHI.SHI.2026-0825 | D13: Cerrada ganada | E13: 842099 | F13: 1 | G13: 46191 | H13: 1815 UFMA- Laboratorio de Áridos | I13: DHI | J13: SHI - Sección Hormigones Ingeniería | K13: Control de áridos mensual planta Las Garzas Junio M-4067893 | L13: 46191 | M13: FALSO
... A387: 763034704 | B387: SANTA LAURA HORMIGONES SPA | C387: PR.DHI.SHI.2026-0013 | D387: Cerrada ganada | E387: 868549 | F387: 1 | G387: 46100 | H387: 2318 UHI - Unidad Hormigones Ingeniería | I387: DHI | J387: SHI - Sección Hormigones Ingeniería | K387: Curva de madurez para muestreo en obra | L387: 46100 | M387: FALSO
B388: CODELCO DIVISION EL TENIENTE | C388: PR.DHI.SHI.2024-0243 | D388: Cerrada ganada | E388: 0 | F388: 1 | G388: 46098 | H388: 2318 UHI - Unidad Hormigones Ingeniería | I388: DHI | J388: SHI - Sección Hormigones Ingeniería | K388: Determinación del porcentaje máximo de reemplazo de relave de cobre como arena en 3 tipos de hormigones | L388: 46098 | M388: FALSO
A389: 769103600 | B389: CONSTRUCTORA SANTOLAYA LTDA | C389: PR.DHI.SHI.2026-0192 Lechada en obra | D389: Cerrada ganada | E389: 1035885 | F389: 1 | G389: 46098 | H389: 2935 LM - Laboratorio Mortero de Prueba | I389: DHI | J389: SHI - Sección Hormigones Ingeniería | K389: Ensayos físicos realizados en terreno | L389: 46098 | M389: FALSO
A390: 898536009 | B390: CONSTRUCTORA INGEVEC S.A. | C390: PR.DHI.SHI.2026-0086 | D390: Cerrada ganada | E390: 5969086 | F390: 1 | G390: 46097 | H390: 2318 UHI - Unidad Hormigones Ingeniería | I390: DHI | J390: SHI - Sección Hormigones Ingeniería | K390: Exploración del hormigón y armadura de elementos pertenecientes al edificio El Aromo | L390: 46097 | M390: FALSO
A391: 781028649 | B391: CONSORCIO BAHIA FILDES SPA | C391: PR.DHI.SHI.2025-0207 | D391: Cerrada ganada | E391: 3252678 | F391: 1 | G391: 46097 | H391: 2935 LM - Laboratorio Mortero de Prueba | I391: DHI | J391: SHI - Sección Hormigones Ingeniería | K391: Ensayo de permeabilidad al agua en probetas moldeadas | L391: 46097 | M391: FALSO
A392: 590593400 | B392: OBRASCÓN HUARTE LAIN S A AGENCIA EN CHILE | C392: PR.DHI.SHI.2026-0034-A | D392: Cerrada ganada | E392: 0 | F392: 1 | G392: 46097 | H392: 2318 UHI - Unidad Hormigones Ingeniería | I392: DHI | J392: SHI - Sección Hormigones Ingeniería | K392: Evaluación Mediante Ultrasonido Del Hormigón De De La Losa Superior De Un Sector Del Túnel Lo Ruiz | L392: 46097 | M392: FALSO
A393: 868567007 | B393: CONSTRUCTORA NOVATEC S.A. | C393: PR.DHI.SHI.2025-1013 | D393: Cerrada ganada | E393: 4661481 | F393: 1 | G393: 46094 | H393: 2935 LM - Laboratorio Mortero de Prueba | I393: DHI | J393: SHI - Sección Hormigones Ingeniería | K393: Ensayos de adherencia efectuados en terreno | L393: 46094 | M393: FALSO
A394: 765252903 | B394: EBCO S.A. | C394: PR.DHI.SHI.2025-1380 | D394: Cerrada ganada | E394: 617547 | F394: 1 | G394: 46091 | H394: 2935 LM - Laboratorio Mortero de Prueba | I394: DHI | J394: SHI - Sección Hormigones Ingeniería | K394: Ensayos físicos realizados en terreno | L394: 46091 | M394: FALSO
A395: 592334100 | B395: China First Highway Engineering Co. Ltd. Agencia En Chile | C395: PR.DHI.SHI.2026-0100-A | D395: Cerrada ganada | E395: 4900110 | F395: 1 | G395: 46086 | H395: 2318 UHI - Unidad Hormigones Ingeniería | I395: DHI | J395: SHI - Sección Hormigones Ingeniería | K395: Evaluación mediante testigos y ultrasonido de las fisuras en el hormigón de una losa en la Central Hidroeléctrica Rucalhue. | L395: 46086 | M395: FALSO
A396: 72307267 | B396: Luis Horacio Olave Polanco | C396: PR.DHI.SHI.2025-1430 | D396: Cerrada ganada | E396: 1504944 | F396: 1 | G396: 46085 | H396: 2318 UHI - Unidad Hormigones Ingeniería | I396: DHI | J396: SHI - Sección Hormigones Ingeniería | K396: Dosificación de hormigones | L396: 46085 | M396: FALSO
A397: 763508714 | B397: AISLANTES NACIONALES SPA | C397: PR.DHI.SHI.2026-0015 | D397: Cerrada ganada | E397: 2582044 | F397: 1 | G397: 46069 | H397: 2935 LM - Laboratorio Mortero de Prueba | I397: DHI | J397: SHI - Sección Hormigones Ingeniería | K397: Ensayos Físicos a Morteros | L397: 46080 | M397: FALSO
A398: 766592007 | B398: CONSTRUCTORA PAZ SPA | C398: PR.DHI.SHI.2026-0037 | D398: Cerrada ganada | E398: 1212058 | F398: 1 | G398: 46064 | H398: 2935 LM - Laboratorio Mortero de Prueba | I398: DHI | J398: SHI - Sección Hormigones Ingeniería | K398: Ensayo de Adherencia en terrreno | L398: 46080 | M398: FALSO
A399: 968897802 | B399: CONSTRUCTORA JORGE CARRASCO FARIAS SPA | C399: PR.DHI.SHI.2026-0182 | D399: Cerrada ganada | E399: 615964 | F399: 1 | G399: 46065 | H399: 2935 LM - Laboratorio Mortero de Prueba | I399: DHI | J399: SHI - Sección Hormigones Ingeniería | K399: Ensayo de Adherencia en Terreno | L399: 46080 | M399: FALSO
A400: 765252903 | B400: EBCO S.A. | C400: PR.DHI.SHI.2025-1541 | D400: Cerrada ganada | E400: 1231524 | F400: 1 | G400: 46064 | H400: 2935 LM - Laboratorio Mortero de Prueba | I400: DHI | J400: SHI - Sección Hormigones Ingeniería | K400: Ensayo de Adherencia en Terreno | L400: 46080 | M400: FALSO
... A832: 760934542 | B832: SAN JOSE CONSTRUCTORA CHILE S.A. | C832: PR.DES.2021-183 | D832: Cerrada ganada | E832: 2203046 | F832: 1 | G832: 44616 | H832: 2124 UIE - Unidad Inspección Especialista | I832: DES | J832: SEP - Sección Especialidades | K832: MEDICIÓN DE RESISTENCIA ELÉCTRICA DE PISOS DE PABELLONES DE HOSPITAL DE HUASCO | L832: 46382 | M832: FALSO
B833: CODELCO VICEPRESIDENCIA DE PROYECTOS | C833: PR.DGI.2022-015_I Otros Tranques (Descontable Orden de Cambio 15) | D833: Cerrada ganada | E833: 34341656 | F833: 1 | G833: 44864 | H833: 1785 USJ - Unidad Sondajes | I833: DGI | J833: SPG - Sección Prospecciones Geotécnicas | K833: Orden de Cambio 15 | L833: 46363 | M833: FALSO
A834: 898536009 | B834: CONSTRUCTORA INGEVEC S.A. | C834: PR.DTC.2026.0115 - Estudio Ventanas El Aromo La Florida | D834: Cerrada ganada | E834: 1 | F834: 1 | G834: 46058 | H834: 3149 RMP - RENAM Privado | I834: DTC | J834: SET - Sección Estudios | K834: PR.DTC.2026.0115 | L834: 46356 | M834: FALSO
A835: 898536009 | B835: CONSTRUCTORA INGEVEC S.A. | C835: PR.DTC.2026.0099 - Estudio Ventanas Franklin Sinergia | D835: Cerrada ganada | E835: 1 | F835: 1 | G835: 45988 | H835: 3149 RMP - RENAM Privado | I835: DTC | J835: SET - Sección Estudios | K835: PR.DTC.2026.0099 | L835: 46356 | M835: FALSO
A836: 898536009 | B836: CONSTRUCTORA INGEVEC S.A. | C836: PR.DTC.2026.0100 - Estudio Ventanas Las Quemas II | D836: Cerrada ganada | E836: 1 | F836: 1 | G836: 45988 | H836: 3149 RMP - RENAM Privado | I836: DTC | J836: SET - Sección Estudios | K836: PR.DTC.2026.0100 | L836: 46356 | M836: FALSO
A837: 898536009 | B837: CONSTRUCTORA INGEVEC S.A. | C837: PR.DTC.2026.0102 - Estudio Ventanas Nueva Esmeralda | D837: Cerrada ganada | E837: 1 | F837: 1 | G837: 46014 | H837: 3149 RMP - RENAM Privado | I837: DTC | J837: SET - Sección Estudios | K837: PR.DTC.2026.0102 | L837: 46356 | M837: FALSO
A838: 898536009 | B838: CONSTRUCTORA INGEVEC S.A. | C838: PR.DTC.2026.0116 - Estudio Ventanas Briones Luco Patagon | D838: Cerrada ganada | E838: 1 | F838: 1 | G838: 46058 | H838: 3149 RMP - RENAM Privado | I838: DTC | J838: SET - Sección Estudios | K838: PR.DTC.2026.0116 | L838: 46356 | M838: FALSO
A839: 898536009 | B839: CONSTRUCTORA INGEVEC S.A. | C839: PR.DTC.2026.0101 - Estudio Ventanas Miraflores Ayacucho | D839: Cerrada ganada | E839: 1 | F839: 1 | G839: 46037 | H839: 3149 RMP - RENAM Privado | I839: DTC | J839: SET - Sección Estudios | K839: PR.DTC.2026.0101 | L839: 46356 | M839: FALSO
A840: 898536009 | B840: CONSTRUCTORA INGEVEC S.A. | C840: PR.DTC.2026.0382 - Estudio Ventanas Diagonal Paraguay | D840: Cerrada ganada | E840: 1 | F840: 1 | G840: 46133 | H840: 3149 RMP - RENAM Privado | I840: DTC | J840: SET - Sección Estudios | K840: PR.DTC.2026.0382 | L840: 46356 | M840: FALSO
A841: 781329479 | B841: Inmobiliaria Actual Lira SpA | C841: PR.DES.2026-90 | D841: Cerrada ganada | E841: 6123863 | F841: 1 | G841: 46205 | H841: 2124 UIE - Unidad Inspección Especialista | I841: DES | J841: SEP - Sección Especialidades | K841: Edificio Lira | L841: 46325 | M841: FALSO
A842: 2366 | B842: DIVISIÓN INSPECCIÓN DE OBRAS | C842: PR.DES.2020-166 | D842: Cerrada ganada | E842: 2292802 | F842: 1 | G842: 44053 | H842: 2124 UIE - Unidad Inspección Especialista | I842: DES | J842: SEP - Sección Especialidades | K842: Sevilla Norte | L842: 46295 | M842: FALSO
A843: 898536009 | B843: CONSTRUCTORA INGEVEC S.A. | C843: PR.DES.2025-89 | D843: Cerrada ganada | E843: 6277712 | F843: 1 | G843: 45826 | H843: 2124 UIE - Unidad Inspección Especialista | I843: DES | J843: SEP - Sección Especialidades | K843: Edificios Domeyko y San Ignacio | L843: 46289 | M843: FALSO
A844: 609100001 | B844: UNIVERSIDAD DE CHILE | C844: PR.DES.2026-108 | D844: Cerrada ganada | E844: 7348635 | F844: 1 | G844: 46205 | H844: 2124 UIE - Unidad Inspección Especialista | I844: DES | J844: SEP - Sección Especialidades | K844: Diagnostico Ascensores Torre 15 | L844: 46289 | M844: FALSO
...

Sheet Año_reporte
A1: Fecha | B1: Comentario
A2: 46387 | B2: Esta fecha cambiarla cada año que se hace el reporte, dejar el último día del año

Sheet Cuadratura
A1: Revisar acumulado EERR vs Div | D1: =SUM(D3:D19) -> 0 | F1: Revisar acumulado SalesForce vs Div | I1: =SUM(I3:I19) -> 0 | K1: Revisar acumulado Diferencia vs Div | N1: =SUM(N3:N19) -> -4.529953e-06 | P1: Revisar Detalle acumulado EERR vs Div | S1: =SUM(S3:S19) -> 0 | U1: Revisar Detalle acumulado SalesForce vs Div | X1: =SUM(X3:X19) -> 0 | Z1: Reporte Facturación
B2: Ingreso EERR | C2: Ingreso DIV | D2: Diferencia | G2: Ingreso EERR | H2: Ingreso DIV | I2: Diferencia | L2: Ingreso EERR | M2: Ingreso DIV | N2: Diferencia | Q2: Ingreso EERR | R2: Ingreso DIV | S2: Diferencia | V2: Ingreso Div Detalle | W2: Ingreso DIV | X2: Diferencia | AA2: =GETPIVOTDATA("[Measures].[Ingreso]",IDIEM!$I$1) -> 22940610337 | AB2: =GETPIVOTDATA("[Measures].[Ingreso]",'Reporte Facturación sin TI'!$A$3) -> 22940610337 | AC2: =AB2-AA2 -> 0
A3: DAC | B3: =GETPIVOTDATA("[Measures].[Ingreso]",IDIEM!$I$1,"[Resultado].[Div]","[Resultado].[Div].&[DAC]") -> 854485347 | C3: =GETPIVOTDATA("[Measures].[Ingreso]",DAC!$I$1,"[Resultado].[Div]","[Resultado].[Div].&[DAC]") -> 854485347 | D3: =C3-B3 -> 0 | F3: DAC | G3: =GETPIVOTDATA("[Measures].[Ingreso_Salesforce]",IDIEM!$I$25,"[TBD_Reporte_Salesforce].[División]","[TBD_Reporte_Salesforce].[División].&[DAC]") -> 1.2797689e+09 | H3: =DAC!V63 -> 1.2797689e+09 | I3: =H3-G3 -> 0 | K3: DAC | L3: =B3-G3 -> -4.2528352e+08 | M3: =DAC!V84 -> -4.2528352e+08 | N3: =L3-M3 -> 0 | P3: DAC | Q3: =GETPIVOTDATA("[Measures].[Ingreso]",DAC!$I$88) -> 854485347 | R3: =GETPIVOTDATA("[Measures].[Ingreso]",DAC!$I$1,"[Resultado].[Div]","[Resultado].[Div].&[DAC]") -> 854485347 | S3: =R3-Q3 -> 0 | U3: DAC | V3: =GETPIVOTDATA("[Measures].[Ingreso_Salesforce]",DAC!$Z$88) -> 1.2797689e+09 | W3: =DAC!V63 -> 1.2797689e+09 | X3: =W3-V3 -> 0
A4: DCO | B4: =GETPIVOTDATA("[Measures].[Ingreso]",IDIEM!$I$1,"[Resultado].[Div]","[Resultado].[Div].&[DCO]") -> 2375406406 | C4: =GETPIVOTDATA("[Measures].[Ingreso]",DCO!$I$1,"[Resultado].[Div]","[Resultado].[Div].&[DCO]") -> 2375406406 | D4: =C4-B4 -> 0 | F4: DCO | G4: =GETPIVOTDATA("[Measures].[Ingreso_Salesforce]",IDIEM!$I$25,"[TBD_Reporte_Salesforce].[División]","[TBD_Reporte_Salesforce].[División].&[DCO]") -> 3.5954668e+09 | H4: =DCO!V63 -> 3.5954668e+09 | I4: =H4-G4 -> 0 | K4: DCO | L4: =B4-G4 -> -1.2200604e+09 | M4: =DCO!V84 -> -1.2200604e+09 | N4: =L4-M4 -> 0 | P4: DCO | Q4: =GETPIVOTDATA("[Measures].[Ingreso]",DCO!$I$88) -> 2375406406 | R4: =GETPIVOTDATA("[Measures].[Ingreso]",DCO!$I$1,"[Resultado].[Div]","[Resultado].[Div].&[DCO]") -> 2375406406 | S4: =R4-Q4 -> 0 | U4: DCO | V4: =GETPIVOTDATA("[Measures].[Ingreso_Salesforce]",DCO!$Z$88) -> 3.5954668e+09 | W4: =DCO!V63 -> 3.5954668e+09 | X4: =W4-V4 -> 0
A5: DDA | B5: =GETPIVOTDATA("[Measures].[Ingreso]",IDIEM!$I$1,"[Resultado].[Div]","[Resultado].[Div].&[DDA]") -> 1611234147 | C5: =GETPIVOTDATA("[Measures].[Ingreso]",DDA!$I$1) -> 1611234147 | D5: =C5-B5 -> 0 | F5: DDA | G5: =GETPIVOTDATA("[Measures].[Ingreso_Salesforce]",IDIEM!$I$25,"[TBD_Reporte_Salesforce].[División]","[TBD_Reporte_Salesforce].[División].&[DDA]") -> 772668938 | H5: =DDA!V63 -> 772668938 | I5: =H5-G5 -> 0 | K5: DDA | L5: =B5-G5 -> 838565209 | M5: =DDA!V84 -> 838565209 | N5: =L5-M5 -> 0 | P5: DDA | Q5: =GETPIVOTDATA("[Measures].[Ingreso]",DDA!$I$88) -> 1611234147 | R5: =GETPIVOTDATA("[Measures].[Ingreso]",DDA!$I$1) -> 1611234147 | S5: =R5-Q5 -> 0 | U5: DDA | V5: =GETPIVOTDATA("[Measures].[Ingreso_Salesforce]",DDA!$Z$88) -> 772668938 | W5: =DDA!V63 -> 772668938 | X5: =W5-V5 -> 0
A6: DEP | B6: =GETPIVOTDATA("[Measures].[Ingreso]",IDIEM!$I$1,"[Resultado].[Div]","[Resultado].[Div].&[DEP]") -> 777676470 | C6: =GETPIVOTDATA("[Measures].[Ingreso]",DEP!$I$1,"[Resultado].[Div]","[Resultado].[Div].&[DEP]") -> 777676470 | D6: =C6-B6 -> 0 | F6: DEP | G6: =GETPIVOTDATA("[Measures].[Ingreso_Salesforce]",IDIEM!$I$25,"[TBD_Reporte_Salesforce].[División]","[TBD_Reporte_Salesforce].[División].&[DEP]") -> 7.1343642e+08 | H6: =DEP!V63 -> 7.1343642e+08 | I6: =H6-G6 -> 0 | K6: DEP | L6: =B6-G6 -> 64240048 | M6: =DEP!V84 -> 64240048 | N6: =L6-M6 -> 5.9604645e-08 | P6: DEP | Q6: =GETPIVOTDATA("[Measures].[Ingreso]",DEP!$I$88) -> 777676470 | R6: =GETPIVOTDATA("[Measures].[Ingreso]",DEP!$I$1,"[Resultado].[Div]","[Resultado].[Div].&[DEP]") -> 777676470 | S6: =R6-Q6 -> 0 | U6: DEP | V6: =GETPIVOTDATA("[Measures].[Ingreso_Salesforce]",DEP!$Z$88) -> 7.1343642e+08 | W6: =DEP!V63 -> 7.1343642e+08 | X6: =W6-V6 -> 0
A7: DES | B7: =GETPIVOTDATA("[Measures].[Ingreso]",IDIEM!$I$1,"[Resultado].[Div]","[Resultado].[Div].&[DES]") -> 1544101259 | C7: =GETPIVOTDATA("[Measures].[Ingreso]",DES!$I$1) -> 1544101259 | D7: =C7-B7 -> 0 | F7: DES | G7: =GETPIVOTDATA("[Measures].[Ingreso_Salesforce]",IDIEM!$I$25,"[TBD_Reporte_Salesforce].[División]","[TBD_Reporte_Salesforce].[División].&[DES]") -> 1.5521385e+09 | H7: =DES!V63 -> 1.5521385e+09 | I7: =H7-G7 -> 0 | K7: DES | L7: =B7-G7 -> -8037197.2 | M7: =DES!V84 -> -8037197.2 | N7: =L7-M7 -> 1.1920929e-07 | P7: DES | Q7: =GETPIVOTDATA("[Measures].[Ingreso]",DES!$I$88) -> 1544101259 | R7: =GETPIVOTDATA("[Measures].[Ingreso]",DES!$I$1) -> 1544101259 | S7: =R7-Q7 -> 0 | U7: DES | V7: =GETPIVOTDATA("[Measures].[Ingreso_Salesforce]",DES!$Z$88) -> 1.5521385e+09 | W7: =DES!V63 -> 1.5521385e+09 | X7: =W7-V7 -> 0
A8: DGI | B8: =GETPIVOTDATA("[Measures].[Ingreso]",IDIEM!$I$1,"[Resultado].[Div]","[Resultado].[Div].&[DGI]") -> 7773506377 | C8: =GETPIVOTDATA("[Measures].[Ingreso]",DGI!$I$1) -> 7773506377 | D8: =C8-B8 -> 0 | F8: DGI | G8: =GETPIVOTDATA("[Measures].[Ingreso_Salesforce]",IDIEM!$I$25,"[TBD_Reporte_Salesforce].[División]","[TBD_Reporte_Salesforce].[División].&[DGI]") -> 8526059472 | H8: =DGI!V63 -> 8526059472 | I8: =H8-G8 -> 0 | K8: DGI | L8: =B8-G8 -> -752553095 | M8: =DGI!V84 -> -752553095 | N8: =L8-M8 -> 0 | P8: DGI | Q8: =GETPIVOTDATA("[Measures].[Ingreso]",DGI!$I$88) -> 7773506377 | R8: =GETPIVOTDATA("[Measures].[Ingreso]",DGI!$I$1) -> 7773506377 | S8: =R8-Q8 -> 0 | U8: DGI | V8: =GETPIVOTDATA("[Measures].[Ingreso_Salesforce]",DGI!$Z$88) -> 8526059472 | W8: =DGI!V63 -> 8526059472 | X8: =W8-V8 -> 0
A9: DGL | B9: =GETPIVOTDATA("[Measures].[Ingreso]",IDIEM!$I$1,"[Resultado].[Div]","[Resultado].[Div].&[DGL]") -> 1996413912 | C9: =GETPIVOTDATA("[Measures].[Ingreso]",DGL!$I$1) -> 1996413912 | D9: =C9-B9 -> 0 | F9: DGL | G9: =GETPIVOTDATA("[Measures].[Ingreso_Salesforce]",IDIEM!$I$25,"[TBD_Reporte_Salesforce].[División]","[TBD_Reporte_Salesforce].[División].&[DGL]") -> 2084836477 | H9: =DGL!V63 -> 2084836477 | I9: =H9-G9 -> 0 | K9: DGL | L9: =B9-G9 -> -88422565 | M9: =DGL!V84 -> -88422565 | N9: =L9-M9 -> 0 | P9: DGL | Q9: =GETPIVOTDATA("[Measures].[Ingreso]",DGL!$I$88) -> 1996413912 | R9: =GETPIVOTDATA("[Measures].[Ingreso]",DGL!$I$1) -> 1996413912 | S9: =R9-Q9 -> 0 | U9: DGL | V9: =GETPIVOTDATA("[Measures].[Ingreso_Salesforce]",DGL!$Z$88) -> 2084836477 | W9: =DGL!V63 -> 2084836477 | X9: =W9-V9 -> 0
A10: DHC | B10: =GETPIVOTDATA("[Measures].[Ingreso]",IDIEM!$I$1,"[Resultado].[Div]","[Resultado].[Div].&[DHC]") -> 1647253291 | C10: =GETPIVOTDATA("[Measures].[Ingreso]",DHC!$I$1) -> 1647253291 | D10: =C10-B10 -> 0 | F10: DHC | G10: =GETPIVOTDATA("[Measures].[Ingreso_Salesforce]",IDIEM!$I$25,"[TBD_Reporte_Salesforce].[División]","[TBD_Reporte_Salesforce].[División].&[DHC]") -> 542858276 | H10: =DHC!V63 -> 542858276 | I10: =H10-G10 -> 0 | K10: DHC | L10: =B10-G10 -> 1104395015 | M10: =DHC!V84 -> 1104395015 | N10: =L10-M10 -> 0 | P10: DHC | Q10: =GETPIVOTDATA("[Measures].[Ingreso]",DHC!$I$88) -> 1647253291 | R10: =GETPIVOTDATA("[Measures].[Ingreso]",DHC!$I$1) -> 1647253291 | S10: =R10-Q10 -> 0 | U10: DHC | V10: =GETPIVOTDATA("[Measures].[Ingreso_Salesforce]",DHC!$Z$88) -> 542858276 | W10: =DHC!V63 -> 542858276 | X10: =W10-V10 -> 0
A11: DHI | B11: =GETPIVOTDATA("[Measures].[Ingreso]",IDIEM!$I$1,"[Resultado].[Div]","[Resultado].[Div].&[DHI]") -> 1467179760 | C11: =GETPIVOTDATA("[Measures].[Ingreso]",DHI!$I$1) -> 1467179760 | D11: =C11-B11 -> 0 | F11: DHI | G11: =GETPIVOTDATA("[Measures].[Ingreso_Salesforce]",IDIEM!$I$25,"[TBD_Reporte_Salesforce].[División]","[TBD_Reporte_Salesforce].[División].&[DHI]") -> 1076834468 | H11: =DHI!V63 -> 1076834468 | I11: =H11-G11 -> 0 | K11: DHI | L11: =B11-G11 -> 390345292 | M11: =DHI!V84 -> 390345292 | N11: =L11-M11 -> 0 | P11: DHI | Q11: =GETPIVOTDATA("[Measures].[Ingreso]",DHI!$I$88) -> 1467179760 | R11: =GETPIVOTDATA("[Measures].[Ingreso]",DHI!$I$1) -> 1467179760 | S11: =R11-Q11 -> 0 | U11: DHI | V11: =GETPIVOTDATA("[Measures].[Ingreso_Salesforce]",DHI!$Z$88) -> 1076834468 | W11: =DHI!V63 -> 1076834468 | X11: =W11-V11 -> 0
A12: DIC | B12: =GETPIVOTDATA("[Measures].[Ingreso]",IDIEM!$I$1,"[Resultado].[Div]","[Resultado].[Div].&[DIC]") -> 312889501 | C12: =GETPIVOTDATA("[Measures].[Ingreso]",DIC!$I$1) -> 312889501 | D12: =C12-B12 -> 0 | F12: DIC | G12: =GETPIVOTDATA("[Measures].[Ingreso_Salesforce]",IDIEM!$I$25,"[TBD_Reporte_Salesforce].[División]","[TBD_Reporte_Salesforce].[División].&[DIC]") -> 312889501 | H12: =DIC!V63 -> 312889501 | I12: =H12-G12 -> 0 | K12: DIC | L12: =B12-G12 -> 0 | M12: =DIC!V84 -> 0 | N12: =L12-M12 -> 0 | P12: DIC | Q12: =GETPIVOTDATA("[Measures].[Ingreso]",DIC!$I$88) -> 312889501 | R12: =GETPIVOTDATA("[Measures].[Ingreso]",DIC!$I$1) -> 312889501 | S12: =R12-Q12 -> 0 | U12: DIC | V12: =GETPIVOTDATA("[Measures].[Ingreso_Salesforce]",DIC!$Z$88) -> 312889501 | W12: =DIC!V63 -> 312889501 | X12: =W12-V12 -> 0
A13: DIO | B13: =GETPIVOTDATA("[Measures].[Ingreso]",IDIEM!$I$1,"[Resultado].[Div]","[Resultado].[Div].&[DIO]") -> 211266786 | C13: =GETPIVOTDATA("[Measures].[Ingreso]",DIO!$I$1) -> 211266786 | D13: =C13-B13 -> 0 | F13: DIO | G13: =GETPIVOTDATA("[Measures].[Ingreso_Salesforce]",IDIEM!$I$25,"[TBD_Reporte_Salesforce].[División]","[TBD_Reporte_Salesforce].[División].&[DIO]") -> 324140668 | H13: =DIO!V63 -> 324140668 | I13: =H13-G13 -> 0 | K13: DIO | L13: =B13-G13 -> -112873882 | M13: =DIO!V84 -> -112873882 | N13: =L13-M13 -> 0 | P13: DIO | Q13: =GETPIVOTDATA("[Measures].[Ingreso]",DIO!$I$88) -> 211266786 | R13: =GETPIVOTDATA("[Measures].[Ingreso]",DIO!$I$1) -> 211266786 | S13: =R13-Q13 -> 0 | U13: DIO | V13: =GETPIVOTDATA("[Measures].[Ingreso_Salesforce]",DIO!$Z$88) -> 324140668 | W13: =DIO!V63 -> 324140668 | X13: =W13-V13 -> 0
A14: DPR | B14: =GETPIVOTDATA("[Measures].[Ingreso]",IDIEM!$I$1,"[Resultado].[Div]","[Resultado].[Div].&[DPR]") -> 1614959968 | C14: =GETPIVOTDATA("[Measures].[Ingreso]",DPR!$I$1) -> 1614959968 | D14: =C14-B14 -> 0 | F14: DPR | G14: =GETPIVOTDATA("[Measures].[Ingreso_Salesforce]",IDIEM!$I$25,"[TBD_Reporte_Salesforce].[División]","[TBD_Reporte_Salesforce].[División].&[DPR]") -> 2980799873 | H14: =DPR!V63 -> 2980799873 | I14: =H14-G14 -> 0 | K14: DPR | L14: =B14-G14 -> -1365839905 | M14: =DPR!V84 -> -1365839905 | N14: =L14-M14 -> 0 | P14: DPR | Q14: =GETPIVOTDATA("[Measures].[Ingreso]",DPR!$I$88) -> 1614959968 | R14: =GETPIVOTDATA("[Measures].[Ingreso]",DPR!$I$1) -> 1614959968 | S14: =R14-Q14 -> 0 | U14: DPR | V14: =GETPIVOTDATA("[Measures].[Ingreso_Salesforce]",DPR!$Z$88) -> 2980799873 | W14: =DPR!V63 -> 2980799873 | X14: =W14-V14 -> 0
A15: DTC | B15: =GETPIVOTDATA("[Measures].[Ingreso]",IDIEM!$I$1,"[Resultado].[Div]","[Resultado].[Div].&[DTC]") -> 1004760047 | C15: =GETPIVOTDATA("[Measures].[Ingreso]",DTC!$I$1) -> 1004760047 | D15: =C15-B15 -> 0 | F15: DTC | G15: =GETPIVOTDATA("[Measures].[Ingreso_Salesforce]",IDIEM!$I$25,"[TBD_Reporte_Salesforce].[División]","[TBD_Reporte_Salesforce].[División].&[DTC]") -> 1.1088036e+09 | H15: =DTC!V63 -> 1.1088036e+09 | I15: =H15-G15 -> 0 | K15: DTC | L15: =B15-G15 -> -1.0404359e+08 | M15: =DTC!V84 -> -1.0404359e+08 | N15: =L15-M15 -> -1.7881393e-07 | P15: DTC | Q15: =GETPIVOTDATA("[Measures].[Ingreso]",DTC!$I$88) -> 1004760047 | R15: =GETPIVOTDATA("[Measures].[Ingreso]",DTC!$I$1) -> 1004760047 | S15: =R15-Q15 -> 0 | U15: DTC | V15: =GETPIVOTDATA("[Measures].[Ingreso_Salesforce]",DTC!$Z$88) -> 1.1088036e+09 | W15: =DTC!V63 -> 1.1088036e+09 | X15: =W15-V15 -> 0
A16: EQM | B16: =GETPIVOTDATA("[Measures].[Ingreso]",IDIEM!$I$1,"[Resultado].[Div]","[Resultado].[Div].&[EQM]") -> -288986146 | C16: =GETPIVOTDATA("[Measures].[Suma de Monto 2]",EQM!$I$1) -> -288986146 | D16: =C16-B16 -> 0 | F16: EQM | G16: =IFERROR(GETPIVOTDATA("[Measures].[Ingreso_Salesforce]",IDIEM!$I$25,"[TBD_Reporte_Salesforce].[División]","[TBD_Reporte_Salesforce].[División].&[EQM]"),0) -> 0 | H16: =EQM!V63 -> 0 | I16: =H16-G16 -> 0 | K16: EQM | L16: =B16-G16 -> -288986146 | M16: =EQM!V84 -> -288986146 | N16: =L16-M16 -> 0 | P16: EQM | Q16: =GETPIVOTDATA("[Measures].[Suma de Monto 2]",EQM!$I$88) -> -288986146 | R16: =GETPIVOTDATA("[Measures].[Suma de Monto 2]",EQM!$I$1) -> -288986146 | S16: =R16-Q16 -> 0 | U16: EQM | V16: 0 | W16: =EQM!V63 -> 0
A17: MDQ | B17: =GETPIVOTDATA("[Measures].[Ingreso]",IDIEM!$I$1,"[Resultado].[Div]","[Resultado].[Div].&[MDQ]") -> 0 | C17: =GETPIVOTDATA("[Measures].[Suma de Monto 2]",MDQ!$I$1) -> 0 | D17: =C17-B17 -> 0 | F17: MDQ | G17: =IFERROR(GETPIVOTDATA("[Measures].[Ingreso_Salesforce]",IDIEM!$I$25,"[TBD_Reporte_Salesforce].[División]","[TBD_Reporte_Salesforce].[División].&[MDQ]"),0) -> 0 | H17: =MDQ!V63 -> 0 | I17: =H17-G17 -> 0 | K17: MDQ | L17: =B17-G17 -> 0 | M17: =MDQ!V84 -> 0 | N17: =L17-M17 -> 0 | P17: MDQ | Q17: =GETPIVOTDATA("[Measures].[Suma de Monto 2]",MDQ!$I$88) -> 0 | R17: =GETPIVOTDATA("[Measures].[Suma de Monto 2]",MDQ!$I$1) -> 0 | S17: =R17-Q17 -> 0 | U17: MDQ | V17: 0 | W17: =MDQ!V63 -> 0 | X17: =W17-V17 -> 0
A18: SDO | B18: =GETPIVOTDATA("[Measures].[Ingreso]",IDIEM!$I$1,"[Resultado].[Div]","[Resultado].[Div].&[SDO]") -> 38463212 | C18: =B18 -> 38463212 | D18: =C18-B18 -> 0 | F18: SDO | K18: SDO | L18: =B18-G18 -> 38463212 | M18: =L18 -> 38463212 | N18: =L18-M18 -> 0
A19: IDIEM | B19: =GETPIVOTDATA("[Measures].[Ingreso]",IDIEM!$I$1) -> 22940610337 | C19: =SUM(C3:C18) -> 22940610337 | D19: =C19-B19 -> 0 | F19: Total general | G19: =GETPIVOTDATA("[Measures].[Ingreso_Salesforce]",IDIEM!$I$25)-GETPIVOTDATA("[Measures].[Ingreso_Salesforce]",IDIEM!$I$25,"[TBD_Reporte_Salesforce].[División]","[TBD_Reporte_Salesforce].[División].&[SDO]") -> 2.4870702e+10 | H19: =SUM(H3:H17) -> 2.4870702e+10 | I19: =H19-G19 -> 0 | K19: IDIEM | L19: =B19-G19 -> -1.9300916e+09 | M19: =SUM(M3:M18) -> -1.9300916e+09 | N19: =L19-M19 -> -4.529953e-06 | P19: IDIEM | Q19: =SUM(Q3:Q17) -> 22902147125 | R19: =SUM(R3:R17) -> 22902147125 | S19: =R19-Q19 -> 0 | U19: IDIEM | V19: =SUM(V3:V17) -> 2.4870702e+10 | W19: =SUM(W3:W17) -> 2.4870702e+10 | X19: =W19-V19 -> 0
V21: EQM y MDQ no tiene nada por Salesforce pero si por EERR, por eso le puse 0

Sheet BBDD Gráficos
A1: Mes Actual
B2: Backlog | C2: (Salesforce) | E2: Facturación | F2: (EERR) | H2: Traspasos | I2: (EERR) | K2: Ingresos (EERR)
B3: Etiquetas de fila | C3: Ingreso_Salesforce | E3: Etiquetas de fila | F3: EERR | H3: Etiquetas de fila | I3: EERR | K3: Etiquetas de fila | L3: EERR
B4: DAC | C4: 3.6332564e+08 | E4: DAC | F4: 501144778 | H4: DAC | I4: 1844000 | K4: DAC | L4: 502988778
B5: DCO | C5: 486320169 | E5: DCO | F5: 202280197 | H5: DCO | I5: -32848612 | K5: DCO | L5: 169431585
B6: DDA | C6: 130045454 | E6: DDA | F6: 268536935 | H6: DEP | I6: 9419648 | K6: DDA | L6: 268536935
B7: DEP | C7: 79488858 | E7: DEP | F7: 151372459 | H7: DES | I7: -71496509 | K7: DEP | L7: 160792107
B8: DES | C8: 3.2742769e+08 | E8: DES | F8: 319390498 | H8: DGI | I8: 38839886 | K8: DES | L8: 247893989
B9: DGI | C9: 1229933471 | E9: DGI | F9: 1585394898 | H9: DGL | I9: 40212085 | K9: DGI | L9: 1624234784
B10: DGL | C10: 436919745 | E10: DGL | F10: 337161507 | H10: DHC | I10: -3120929 | K10: DGL | L10: 377373592
B11: DHC | C11: 146170041 | E11: DHC | F11: 339732550 | H11: DHI | I11: 53055793 | K11: DHC | L11: 336611621
B12: DHI | C12: 125279423 | E12: DHI | F12: 243547684 | H12: DIC | I12: -1608004 | K12: DHI | L12: 296603477
B13: DIC | C13: 41091978 | E13: DIC | F13: 41091978 | H13: DPR | I13: -51606392 | K13: DIC | L13: 39483974
B14: DIO | C14: 47567549 | E14: DIO | F14: 44774892 | H14: DTC | I14: 17309034 | K14: DIO | L14: 44774892
B15: DPR | C15: 492863760 | E15: DPR | F15: 442422045 | H15: Total general | I15: 0 | K15: DPR | L15: 390815653
B16: DTC | C16: 2.1220769e+08 | E16: DTC | F16: 159210040 | K16: DTC | L16: 176519074
B17: SDG | C17: 444000 | E17: EQM | F17: -206156436 | K17: EQM | L17: -206156436
B18: SDO | C18: 4465971 | E18: SDO | F18: 7007326 | K18: SDO | L18: 7007326
B19: Total general | C19: 4.1235514e+09 | E19: Total general | F19: 4436911351 | K19: Total general | L19: 4436911351
A22: Datos para gráficos
B23: Backlog | C23: Facturación | D23: Traspasos | E23: Ingresos (EERR) | F23: Diferencia
A24: DAC | B24: =IFERROR(VLOOKUP($A24,$B$4:$C$19,2,0),0) -> 3.6332564e+08 | C24: =IFERROR(VLOOKUP($A24,$E$4:$F$19,2,0),0) -> 501144778 | D24: =IFERROR(VLOOKUP($A24,$H$4:$I$19,2,0),0) -> 1844000 | E24: =IFERROR(VLOOKUP($A24,$K$4:$L$19,2,0),0) -> 502988778 | F24: =B24-C24 -> -1.3781914e+08
A25: DCO | B25: =IFERROR(VLOOKUP($A25,$B$4:$C$19,2,0),0) -> 486320169 | C25: =IFERROR(VLOOKUP($A25,$E$4:$F$19,2,0),0) -> 202280197 | D25: =IFERROR(VLOOKUP($A25,$H$4:$I$19,2,0),0) -> -32848612 | E25: =IFERROR(VLOOKUP($A25,$K$4:$L$19,2,0),0) -> 169431585 | F25: =B25-C25 -> 284039972
A26: DEP | B26: =IFERROR(VLOOKUP($A26,$B$4:$C$19,2,0),0) -> 79488858 | C26: =IFERROR(VLOOKUP($A26,$E$4:$F$19,2,0),0) -> 151372459 | D26: =IFERROR(VLOOKUP($A26,$H$4:$I$19,2,0),0) -> 9419648 | E26: =IFERROR(VLOOKUP($A26,$K$4:$L$19,2,0),0) -> 160792107 | F26: =B26-C26 -> -71883601
A27: DES | B27: =IFERROR(VLOOKUP($A27,$B$4:$C$19,2,0),0) -> 3.2742769e+08 | C27: =IFERROR(VLOOKUP($A27,$E$4:$F$19,2,0),0) -> 319390498 | D27: =IFERROR(VLOOKUP($A27,$H$4:$I$19,2,0),0) -> -71496509 | E27: =IFERROR(VLOOKUP($A27,$K$4:$L$19,2,0),0) -> 247893989 | F27: =B27-C27 -> 8037196.8
A28: DGI | B28: =IFERROR(VLOOKUP($A28,$B$4:$C$19,2,0),0) -> 1229933471 | C28: =IFERROR(VLOOKUP($A28,$E$4:$F$19,2,0),0) -> 1585394898 | D28: =IFERROR(VLOOKUP($A28,$H$4:$I$19,2,0),0) -> 38839886 | E28: =IFERROR(VLOOKUP($A28,$K$4:$L$19,2,0),0) -> 1624234784 | F28: =B28-C28 -> -355461427
A29: DGL | B29: =IFERROR(VLOOKUP($A29,$B$4:$C$19,2,0),0) -> 436919745 | C29: =IFERROR(VLOOKUP($A29,$E$4:$F$19,2,0),0) -> 337161507 | D29: =IFERROR(VLOOKUP($A29,$H$4:$I$19,2,0),0) -> 40212085 | E29: =IFERROR(VLOOKUP($A29,$K$4:$L$19,2,0),0) -> 377373592 | F29: =B29-C29 -> 99758238
A30: DHC | B30: =IFERROR(VLOOKUP($A30,$B$4:$C$19,2,0),0) -> 146170041 | C30: =IFERROR(VLOOKUP($A30,$E$4:$F$19,2,0),0) -> 339732550 | D30: =IFERROR(VLOOKUP($A30,$H$4:$I$19,2,0),0) -> -3120929 | E30: =IFERROR(VLOOKUP($A30,$K$4:$L$19,2,0),0) -> 336611621 | F30: =B30-C30 -> -193562509
A31: DHI | B31: =IFERROR(VLOOKUP($A31,$B$4:$C$19,2,0),0) -> 125279423 | C31: =IFERROR(VLOOKUP($A31,$E$4:$F$19,2,0),0) -> 243547684 | D31: =IFERROR(VLOOKUP($A31,$H$4:$I$19,2,0),0) -> 53055793 | E31: =IFERROR(VLOOKUP($A31,$K$4:$L$19,2,0),0) -> 296603477 | F31: =B31-C31 -> -118268261
A32: DIC | B32: =IFERROR(VLOOKUP($A32,$B$4:$C$19,2,0),0) -> 41091978 | C32: =IFERROR(VLOOKUP($A32,$E$4:$F$19,2,0),0) -> 41091978 | D32: =IFERROR(VLOOKUP($A32,$H$4:$I$19,2,0),0) -> -1608004 | E32: =IFERROR(VLOOKUP($A32,$K$4:$L$19,2,0),0) -> 39483974 | F32: =B32-C32 -> 0
A33: DIO | B33: =IFERROR(VLOOKUP($A33,$B$4:$C$19,2,0),0) -> 47567549 | C33: =IFERROR(VLOOKUP($A33,$E$4:$F$19,2,0),0) -> 44774892 | D33: =IFERROR(VLOOKUP($A33,$H$4:$I$19,2,0),0) -> 0 | E33: =IFERROR(VLOOKUP($A33,$K$4:$L$19,2,0),0) -> 44774892 | F33: =B33-C33 -> 2792657
A34: DDA | B34: =IFERROR(VLOOKUP($A34,$B$4:$C$19,2,0),0) -> 130045454 | C34: =IFERROR(VLOOKUP($A34,$E$4:$F$19,2,0),0) -> 268536935 | D34: =IFERROR(VLOOKUP($A34,$H$4:$I$19,2,0),0) -> 0 | E34: =IFERROR(VLOOKUP($A34,$K$4:$L$19,2,0),0) -> 268536935 | F34: =B34-C34 -> -138491481
A35: DPR | B35: =IFERROR(VLOOKUP($A35,$B$4:$C$19,2,0),0) -> 492863760 | C35: =IFERROR(VLOOKUP($A35,$E$4:$F$19,2,0),0) -> 442422045 | D35: =IFERROR(VLOOKUP($A35,$H$4:$I$19,2,0),0) -> -51606392 | E35: =IFERROR(VLOOKUP($A35,$K$4:$L$19,2,0),0) -> 390815653 | F35: =B35-C35 -> 50441715
... A39: EQM | B39: =IFERROR(VLOOKUP($A39,$B$4:$C$19,2,0),0) -> 0 | C39: =IFERROR(VLOOKUP($A39,$E$4:$F$19,2,0),0) -> -206156436 | D39: =IFERROR(VLOOKUP($A39,$H$4:$I$19,2,0),0) -> 0 | E39: =IFERROR(VLOOKUP($A39,$K$4:$L$19,2,0),0) -> -206156436 | F39: =B39-C39 -> 206156436
A40: IDIEM | B40: =SUM(B24:B39) -> 4.1231074e+09 | C40: =SUM(C24:C39) -> 4436911351 | D40: =SUM(D24:D39) -> 0 | E40: =SUM(E24:E39) -> 4436911351 | F40: =B40-C40 -> -3.1380391e+08
B41: =B40-C18 -> 4.1186415e+09 | C41: =C40-GETPIVOTDATA("[Measures].[Ingreso]",$E$3) -> 0 | D41: =D40-GETPIVOTDATA("[Measures].[Ingreso]",$H$3) -> 0 | E41: =E40-GETPIVOTDATA("[Measures].[Ingreso]",$K$3) -> 0 | F41: =B41-C41 -> 4.1186415e+09

Sheet IDIEM
I1: EERR s/TI Fact | J1: Etiquetas de columna
I2: Etiquetas de fila | J2: ene | K2: feb | L2: mar | M2: abr | N2: may | O2: jun | P2: jul | Q2: ago | R2: sep | S2: oct | T2: nov | U2: dic | V2: Total general
I3: DAC | J3: -171901206 | K3: 229661282 | L3: 169799213 | M3: 202455970 | N3: -76674690 | O3: 501144778 | V3: 854485347
I4: DCO | J4: 206690743 | K4: 512465962 | L4: 555906372 | M4: 323393211 | N4: 574669921 | O4: 202280197 | V4: 2375406406
I5: DDA | J5: 253505267 | K5: 260928783 | L5: 243506035 | M5: 317466070 | N5: 267291057 | O5: 268536935 | V5: 1611234147
I6: DEP | J6: 100713842 | K6: 103734301 | L6: 148678005 | M6: 137835819 | N6: 135342044 | O6: 151372459 | V6: 777676470
I7: DES | J7: 289140060 | K7: 257502742 | L7: 270815880 | M7: 267801174 | N7: 139450905 | O7: 319390498 | V7: 1544101259
I8: DGI | J8: 1271029488 | K8: 1406463891 | L8: 1338014616 | M8: -14883670 | N8: 2187487154 | O8: 1585394898 | V8: 7773506377
I9: DGL | J9: 286168992 | K9: 338984671 | L9: 241489944 | M9: 451087812 | N9: 341520986 | O9: 337161507 | V9: 1996413912
I10: DHC | J10: 243964570 | K10: 254759929 | L10: 270545544 | M10: 278000887 | N10: 260249811 | O10: 339732550 | V10: 1647253291
I11: DHI | J11: 247050882 | K11: 233153774 | L11: 266744910 | M11: 257612262 | N11: 219070248 | O11: 243547684 | V11: 1467179760
I12: DIC | J12: 16026670 | K12: 57914174 | L12: 25901536 | M12: 90119211 | N12: 81835932 | O12: 41091978 | V12: 312889501
I13: DIO | J13: 55747322 | K13: 55969812 | L13: 55377307 | M13: 48320406 | N13: -48922953 | O13: 44774892 | V13: 211266786
I14: DPR | J14: -78263649 | K14: 344738594 | L14: 360099288 | M14: 185834816 | N14: 360128874 | O14: 442422045 | V14: 1614959968
... I16: EQM | J16: -288986146 | K16: 288986146 | L16: 0 | M16: 0 | N16: -82829710 | O16: -206156436 | V16: -288986146
I17: MDQ | J17: 45730726 | K17: 0 | L17: 0 | M17: 0 | N17: -45730726 | V17: 0
A18: Facturación: Incluye Facturación externa y Traspasos de Servicios Internos | I18: SDO | J18: 4150871 | K18: 2970636 | L18: 10337952 | M18: 7262276 | N18: 6734151 | O18: 7007326 | V18: 38463212
A19: Traspasos: Corresponde solo a Traspasos de Facturación | I19: Total general | J19: 2573481448 | K19: 4525070140 | L19: 4144195780 | M19: 2761451807 | N19: 4499499811 | O19: 4436911351 | V19: 22940610337
A20: Valor en círculo: Representa diferncia entre Backlog y Facturación
I24: Se descarga de SalesForce a traves de una planilla de google sheets
I25: Ingreso_Salesforce | J25: Etiquetas de columna
I26: Etiquetas de fila | J26: ene | K26: feb | L26: mar | M26: abr | N26: may | O26: jun | P26: Total general
I27: DAC | J27: -169531556 | K27: 229661282 | L27: 132474079 | M27: 254268998 | N27: 4.6957042e+08 | O27: 3.6332564e+08 | P27: 1.2797689e+09
I28: DCO | J28: 842635563 | K28: 592333115 | L28: 354793861 | M28: 4.2707473e+08 | N28: 892309408 | O28: 486320169 | P28: 3.5954668e+09
I29: DDA | J29: 181228409 | K29: 129936364 | L29: 134027273 | M29: 157001893 | N29: 40429545 | O29: 130045454 | P29: 772668938
I30: DEP | J30: 27617921 | K30: 1.7119322e+08 | L30: 2.5230381e+08 | M30: 1.2067604e+08 | N30: 62156575 | O30: 79488858 | P30: 7.1343642e+08
I31: DES | J31: 289140060 | K31: 2.5750274e+08 | L31: 270815880 | M31: 267801174 | N31: 1.3945091e+08 | O31: 3.2742769e+08 | P31: 1.5521385e+09
I32: DGI | J32: 1271029488 | K32: 1406463891 | L32: 1321970041 | M32: -137844577 | N32: 3434507158 | O32: 1229933471 | P32: 8526059472
I33: DGL | J33: 286168992 | K33: 338984671 | L33: 230154271 | M33: 451087812 | N33: 341520986 | O33: 436919745 | P33: 2084836477
I34: DHC | J34: 73086361 | K34: 73231017 | L34: 80734296 | M34: 85650722 | N34: 83985839 | O34: 146170041 | P34: 542858276
I35: DHI | J35: 218731800 | K35: 172601844 | L35: 161539048 | M35: 196879192 | N35: 201803161 | O35: 125279423 | P35: 1076834468
I36: DIC | J36: 16026670 | K36: 57914174 | L36: 25901536 | M36: 90119211 | N36: 81835932 | O36: 41091978 | P36: 312889501
I37: DIO | J37: 50982594 | K37: 54985753 | L37: 42216285 | M37: 80987512 | N37: 47400975 | O37: 47567549 | P37: 324140668
I38: DPR | J38: 522514884 | K38: 478946114 | L38: 4.0956632e+08 | M38: 5.4676366e+08 | N38: 530145136 | O38: 492863760 | P38: 2980799873
... I41: Total general | J41: 3.7150929e+09 | K41: 4.1173616e+09 | L41: 3.6396797e+09 | M41: 2.7135035e+09 | N41: 6.583573e+09 | O41: 4.1231074e+09 | P41: 2.4892318e+10
I47: Salesforce | J47: Ene | K47: Feb | L47: Mar | M47: Abr | N47: May | O47: Jun | P47: Jul | Q47: Ago | R47: Sep | S47: Oct | T47: Nov | U47: Dic | V47: Total
I48: DAC | J48: =IFERROR(VLOOKUP($I48,$I$26:$V$42,MATCH(J$47,$I$26:$V$26,0),0),0) -> -169531556 | K48: =IFERROR(VLOOKUP($I48,$I$26:$V$42,MATCH(K$47,$I$26:$V$26,0),0),0) -> 229661282 | L48: =IFERROR(VLOOKUP($I48,$I$26:$V$42,MATCH(L$47,$I$26:$V$26,0),0),0) -> 132474079 | M48: =IFERROR(VLOOKUP($I48,$I$26:$V$42,MATCH(M$47,$I$26:$V$26,0),0),0) -> 254268998 | N48: =IFERROR(VLOOKUP($I48,$I$26:$V$42,MATCH(N$47,$I$26:$V$26,0),0),0) -> 4.6957042e+08 | O48: =IFERROR(VLOOKUP($I48,$I$26:$V$42,MATCH(O$47,$I$26:$V$26,0),0),0) -> 3.6332564e+08 | P48: =IFERROR(VLOOKUP($I48,$I$26:$V$42,MATCH(P$47,$I$26:$V$26,0),0),0) -> 0 | Q48: =IFERROR(VLOOKUP($I48,$I$26:$V$42,MATCH(Q$47,$I$26:$V$26,0),0),0) -> 0 | ... U48: =IFERROR(VLOOKUP($I48,$I$26:$V$42,MATCH(U$47,$I$26:$V$26,0),0),0) -> 0 | V48: =SUM(J48:U48) -> 1.2797689e+09
I49: DCO | J49: =IFERROR(VLOOKUP($I49,$I$26:$V$42,MATCH(J$47,$I$26:$V$26,0),0),0) -> 842635563 | K49: =IFERROR(VLOOKUP($I49,$I$26:$V$42,MATCH(K$47,$I$26:$V$26,0),0),0) -> 592333115 | L49: =IFERROR(VLOOKUP($I49,$I$26:$V$42,MATCH(L$47,$I$26:$V$26,0),0),0) -> 354793861 | M49: =IFERROR(VLOOKUP($I49,$I$26:$V$42,MATCH(M$47,$I$26:$V$26,0),0),0) -> 4.2707473e+08 | N49: =IFERROR(VLOOKUP($I49,$I$26:$V$42,MATCH(N$47,$I$26:$V$26,0),0),0) -> 892309408 | O49: =IFERROR(VLOOKUP($I49,$I$26:$V$42,MATCH(O$47,$I$26:$V$26,0),0),0) -> 486320169 | P49: =IFERROR(VLOOKUP($I49,$I$26:$V$42,MATCH(P$47,$I$26:$V$26,0),0),0) -> 0 | Q49: =IFERROR(VLOOKUP($I49,$I$26:$V$42,MATCH(Q$47,$I$26:$V$26,0),0),0) -> 0 | ... U49: =IFERROR(VLOOKUP($I49,$I$26:$V$42,MATCH(U$47,$I$26:$V$26,0),0),0) -> 0 | V49: =SUM(J49:U49) -> 3.5954668e+09
I50: DEP | J50: =IFERROR(VLOOKUP($I50,$I$26:$V$42,MATCH(J$47,$I$26:$V$26,0),0),0) -> 27617921 | K50: =IFERROR(VLOOKUP($I50,$I$26:$V$42,MATCH(K$47,$I$26:$V$26,0),0),0) -> 1.7119322e+08 | L50: =IFERROR(VLOOKUP($I50,$I$26:$V$42,MATCH(L$47,$I$26:$V$26,0),0),0) -> 2.5230381e+08 | M50: =IFERROR(VLOOKUP($I50,$I$26:$V$42,MATCH(M$47,$I$26:$V$26,0),0),0) -> 1.2067604e+08 | N50: =IFERROR(VLOOKUP($I50,$I$26:$V$42,MATCH(N$47,$I$26:$V$26,0),0),0) -> 62156575 | O50: =IFERROR(VLOOKUP($I50,$I$26:$V$42,MATCH(O$47,$I$26:$V$26,0),0),0) -> 79488858 | P50: =IFERROR(VLOOKUP($I50,$I$26:$V$42,MATCH(P$47,$I$26:$V$26,0),0),0) -> 0 | Q50: =IFERROR(VLOOKUP($I50,$I$26:$V$42,MATCH(Q$47,$I$26:$V$26,0),0),0) -> 0 | ... U50: =IFERROR(VLOOKUP($I50,$I$26:$V$42,MATCH(U$47,$I$26:$V$26,0),0),0) -> 0 | V50: =SUM(J50:U50) -> 7.1343642e+08
I51: DES | J51: =IFERROR(VLOOKUP($I51,$I$26:$V$42,MATCH(J$47,$I$26:$V$26,0),0),0) -> 289140060 | K51: =IFERROR(VLOOKUP($I51,$I$26:$V$42,MATCH(K$47,$I$26:$V$26,0),0),0) -> 2.5750274e+08 | L51: =IFERROR(VLOOKUP($I51,$I$26:$V$42,MATCH(L$47,$I$26:$V$26,0),0),0) -> 270815880 | M51: =IFERROR(VLOOKUP($I51,$I$26:$V$42,MATCH(M$47,$I$26:$V$26,0),0),0) -> 267801174 | N51: =IFERROR(VLOOKUP($I51,$I$26:$V$42,MATCH(N$47,$I$26:$V$26,0),0),0) -> 1.3945091e+08 | O51: =IFERROR(VLOOKUP($I51,$I$26:$V$42,MATCH(O$47,$I$26:$V$26,0),0),0) -> 3.2742769e+08 | P51: =IFERROR(VLOOKUP($I51,$I$26:$V$42,MATCH(P$47,$I$26:$V$26,0),0),0) -> 0 | Q51: =IFERROR(VLOOKUP($I51,$I$26:$V$42,MATCH(Q$47,$I$26:$V$26,0),0),0) -> 0 | ... U51: =IFERROR(VLOOKUP($I51,$I$26:$V$42,MATCH(U$47,$I$26:$V$26,0),0),0) -> 0 | V51: =SUM(J51:U51) -> 1.5521385e+09
...

Sheet DAC
I1: EERR s/TI Fact | J1: Etiquetas de columna
I2: Etiquetas de fila | J2: ene | K2: feb | L2: mar | M2: abr | N2: may | O2: jun | P2: jul | Q2: ago | R2: sep | S2: oct | T2: nov | U2: dic | V2: Total general
I3: DAC | J3: -171901206 | K3: 229661282 | L3: 169799213 | M3: 202455970 | N3: -76674690 | O3: 501144778 | V3: 854485347
I4: Total general | J4: -171901206 | K4: 229661282 | L4: 169799213 | M4: 202455970 | N4: -76674690 | O4: 501144778 | V4: 854485347
I25: Ingreso_Salesforce | J25: Etiquetas de columna
I26: Etiquetas de fila | J26: ene | K26: feb | L26: mar | M26: abr | N26: may | O26: jun | P26: Total general
I27: DAC | J27: -169531556 | K27: 229661282 | L27: 132474079 | M27: 254268998 | N27: 4.6957042e+08 | O27: 3.6332564e+08 | P27: 1.2797689e+09
I28: DCO | J28: 842635563 | K28: 592333115 | L28: 354793861 | M28: 4.2707473e+08 | N28: 892309408 | O28: 486320169 | P28: 3.5954668e+09
I29: DDA | J29: 181228409 | K29: 129936364 | L29: 134027273 | M29: 157001893 | N29: 40429545 | O29: 130045454 | P29: 772668938
I30: DEP | J30: 27617921 | K30: 1.7119322e+08 | L30: 2.5230381e+08 | M30: 1.2067604e+08 | N30: 62156575 | O30: 79488858 | P30: 7.1343642e+08
I31: DES | J31: 289140060 | K31: 2.5750274e+08 | L31: 270815880 | M31: 267801174 | N31: 1.3945091e+08 | O31: 3.2742769e+08 | P31: 1.5521385e+09
I32: DGI | J32: 1271029488 | K32: 1406463891 | L32: 1321970041 | M32: -137844577 | N32: 3434507158 | O32: 1229933471 | P32: 8526059472
I33: DGL | J33: 286168992 | K33: 338984671 | L33: 230154271 | M33: 451087812 | N33: 341520986 | O33: 436919745 | P33: 2084836477
I34: DHC | J34: 73086361 | K34: 73231017 | L34: 80734296 | M34: 85650722 | N34: 83985839 | O34: 146170041 | P34: 542858276
I35: DHI | J35: 218731800 | K35: 172601844 | L35: 161539048 | M35: 196879192 | N35: 201803161 | O35: 125279423 | P35: 1076834468
I36: DIC | J36: 16026670 | K36: 57914174 | L36: 25901536 | M36: 90119211 | N36: 81835932 | O36: 41091978 | P36: 312889501
I37: DIO | J37: 50982594 | K37: 54985753 | L37: 42216285 | M37: 80987512 | N37: 47400975 | O37: 47567549 | P37: 324140668
I38: DPR | J38: 522514884 | K38: 478946114 | L38: 4.0956632e+08 | M38: 5.4676366e+08 | N38: 530145136 | O38: 492863760 | P38: 2980799873
I39: DTC | J39: 1.0186675e+08 | K39: 1.5340891e+08 | L39: 2.1757082e+08 | M39: 1.6916078e+08 | N39: 2.5458868e+08 | O39: 2.1220769e+08 | P39: 1.1088036e+09
I40: SDG | O40: 444000 | P40: 444000
I41: SDO | J41: 3594914 | K41: 198466 | L41: 5612144 | M41: 3876374 | N41: 3868251 | O41: 4465971 | P41: 21616120
I42: Total general | J42: 3.7150929e+09 | K42: 4.1173616e+09 | L42: 3.6396797e+09 | M42: 2.7135035e+09 | N42: 6.583573e+09 | O42: 4.1235514e+09 | P42: 2.4892762e+10
I62: Salesforce | J62: Ene | K62: Feb | L62: Mar | M62: Abr | N62: May | O62: Jun | P62: Jul | Q62: Ago | R62: Sep | S62: Oct | T62: Nov | U62: Dic | V62: Total
I63: DAC | J63: =IFERROR(VLOOKUP($I63,$I$26:$V$42,MATCH(J$62,$I$26:$V$26,0),0),0) -> -169531556 | K63: =IFERROR(VLOOKUP($I63,$I$26:$V$42,MATCH(K$62,$I$26:$V$26,0),0),0) -> 229661282 | L63: =IFERROR(VLOOKUP($I63,$I$26:$V$42,MATCH(L$62,$I$26:$V$26,0),0),0) -> 132474079 | M63: =IFERROR(VLOOKUP($I63,$I$26:$V$42,MATCH(M$62,$I$26:$V$26,0),0),0) -> 254268998 | N63: =IFERROR(VLOOKUP($I63,$I$26:$V$42,MATCH(N$62,$I$26:$V$26,0),0),0) -> 4.6957042e+08 | O63: =IFERROR(VLOOKUP($I63,$I$26:$V$42,MATCH(O$62,$I$26:$V$26,0),0),0) -> 3.6332564e+08 | P63: =IFERROR(VLOOKUP($I63,$I$26:$V$42,MATCH(P$62,$I$26:$V$26,0),0),0) -> 0 | Q63: =IFERROR(VLOOKUP($I63,$I$26:$V$42,MATCH(Q$62,$I$26:$V$26,0),0),0) -> 0 | ... U63: =IFERROR(VLOOKUP($I63,$I$26:$V$42,MATCH(U$62,$I$26:$V$26,0),0),0) -> 0 | V63: =SUM(J63:U63) -> 1.2797689e+09
I83: Diferencia | J83: Ene | K83: Feb | L83: Mar | M83: Abr | N83: May | O83: Jun | P83: Jul | Q83: Ago | R83: Sep | S83: Oct | T83: Nov | U83: Dic | V83: Total
I84: DAC | J84: =-IFERROR(VLOOKUP($I84,$I$62:$U$80,MATCH(J$83,$I$62:$U$62,0),0),0)+IFERROR(VLOOKUP($I84,$I$2:$U$23,MATCH(J$83,$I$2:$U$2,0),0),0) -> -2369650 | K84: =-IFERROR(VLOOKUP($I84,$I$62:$U$80,MATCH(K$83,$I$62:$U$62,0),0),0)+IFERROR(VLOOKUP($I84,$I$2:$U$23,MATCH(K$83,$I$2:$U$2,0),0),0) -> 0 | L84: =-IFERROR(VLOOKUP($I84,$I$62:$U$80,MATCH(L$83,$I$62:$U$62,0),0),0)+IFERROR(VLOOKUP($I84,$I$2:$U$23,MATCH(L$83,$I$2:$U$2,0),0),0) -> 37325134 | M84: =-IFERROR(VLOOKUP($I84,$I$62:$U$80,MATCH(M$83,$I$62:$U$62,0),0),0)+IFERROR(VLOOKUP($I84,$I$2:$U$23,MATCH(M$83,$I$2:$U$2,0),0),0) -> -51813028 | N84: =-IFERROR(VLOOKUP($I84,$I$62:$U$80,MATCH(N$83,$I$62:$U$62,0),0),0)+IFERROR(VLOOKUP($I84,$I$2:$U$23,MATCH(N$83,$I$2:$U$2,0),0),0) -> -5.4624511e+08 | O84: =-IFERROR(VLOOKUP($I84,$I$62:$U$80,MATCH(O$83,$I$62:$U$62,0),0),0)+IFERROR(VLOOKUP($I84,$I$2:$U$23,MATCH(O$83,$I$2:$U$2,0),0),0) -> 1.3781914e+08 | P84: =-IFERROR(VLOOKUP($I84,$I$62:$U$80,MATCH(P$83,$I$62:$U$62,0),0),0)+IFERROR(VLOOKUP($I84,$I$2:$U$23,MATCH(P$83,$I$2:$U$2,0),0),0) -> 0 | Q84: =-IFERROR(VLOOKUP($I84,$I$62:$U$80,MATCH(Q$83,$I$62:$U$62,0),0),0)+IFERROR(VLOOKUP($I84,$I$2:$U$23,MATCH(Q$83,$I$2:$U$2,0),0),0) -> 0 | ... U84: =-IFERROR(VLOOKUP($I84,$I$62:$U$80,MATCH(U$83,$I$62:$U$62,0),0),0)+IFERROR(VLOOKUP($I84,$I$2:$U$23,MATCH(U$83,$I$2:$U$2,0),0),0) -> 0 | V84: =SUM(J84:U84) -> -4.2528352e+08
I86: siglaDivision | J86: DAC | Z86: División | AA86: DAC
I88: EERR s/TI Fact | L88: fecha (mes) | Z88: Ingreso_Salesforce | AA88: Etiquetas de columna
A89: Facturación: Incluye Facturación externa y Traspasos de Servicios Internos | I89: Clasificación | J89: cuenta_contable_full | K89: Referencia Interna | L89: ene | M89: feb | N89: mar | O89: abr | P89: may | Q89: jun | R89: Total general | Z89: Etiquetas de fila | AA89: ene | AB89: feb | AC89: mar | AD89: abr | AE89: may | AF89: jun | AG89: Total general
A90: Traspasos: Corresponde solo a Traspasos de Facturación | I90: Ingresos | J90: 61010302 Asesorías y consultorías exterior | K90: PR.DAC.2026.0055 | M90: 3550450 | R90: 3550450 | Z90: N°PR.DAC.2026.0284 | AE90: 1454693 | AG90: 1454693
A91: Valor en círculo: Representa diferncia entre Backlog y Facturación | I91: Ingresos | J91: 61010323 Análisis de materiales | L91: 4501515 | N91: 78527700 | O91: 69916467 | P91: 8785334 | Q91: 82356400 | R91: 244087416 | Z91: PR.DAC.2019.0644E | AA91: 2879620 | AB91: 0 | AC91: 8625735 | AD91: 2907750 | AE91: 2938148 | AF91: 2958094 | AG91: 20309347
I92: Ingresos | J92: 61010323 Análisis de materiales | K92: N°PR.DAC.2026.0284 | P92: 1451666 | R92: 1451666 | Z92: PR.DAC.2019.432 abril 2026 | AE92: 8024040 | AG92: 8024040
I93: Ingresos | J93: 61010323 Análisis de materiales | K93: PR.DAC.2019.0644E | L93: 5753880 | M93: 2879620 | N93: -2870293 | O93: 11496028 | P93: 54127 | Q93: 2938148 | R93: 20251510 | Z93: PR.DAC.2019.432 enero 2026 | AA93: 0 | AB93: 0 | AG93: 0
I94: Ingresos | J94: 61010323 Análisis de materiales | K94: PR.DAC.2019.432 abril 2026 | P94: 8024040 | R94: 8024040 | Z94: PR.DAC.2019.432 febrero 2026 | AB94: 7958126 | AC94: 0 | AG94: 7958126
I95: Ingresos | J95: 61010323 Análisis de materiales | K95: PR.DAC.2019.432 diciembre 2025 | L95: 7945592 | R95: 7945592 | Z95: PR.DAC.2019.432 marzo 2026 | AC95: 7968344 | AG95: 7968344
I96: Ingresos | J96: 61010323 Análisis de materiales | K96: PR.DAC.2019.432 enero 2026 | M96: 7941214 | R96: 7941214 | Z96: PR.DAC.2019.432 mayo 2026 | AF96: 8122138 | AG96: 8122138
I97: Ingresos | J97: 61010323 Análisis de materiales | K97: PR.DAC.2019.432 febrero 2026 | N97: 7958126 | R97: 7958126 | Z97: PR.DAC.2021.0237D Sept a Abr 2026 | AA97: 1351276 | AB97: 16659278 | AC97: 6898195 | AD97: 10802700 | AG97: 35711449
I98: Ingresos | J98: 61010323 Análisis de materiales | K98: PR.DAC.2019.432 marzo 2026 | O98: 7968344 | R98: 7968344 | Z98: PR.DAC.2021.0390AD | AA98: -4910984 | AG98: -4910984
I99: Ingresos | J99: 61010323 Análisis de materiales | K99: PR.DAC.2019.432 mayo 2026 | Q99: 8122138 | R99: 8122138 | Z99: PR.DAC.2021.0390AF | AA99: -2498748 | AG99: -2498748
I100: Ingresos | J100: 61010323 Análisis de materiales | K100: PR.DAC.2021.0237D Sept a Abr 2026 | M100: 20533796 | N100: 5739776 | O100: 0 | R100: 26273572 | Z100: PR.DAC.2021.0390AI | AA100: -1256714 | AG100: -1256714
...

Sheet DCO
I1: EERR s/TI Fact | J1: Etiquetas de columna
I2: Etiquetas de fila | J2: ene | K2: feb | L2: mar | M2: abr | N2: may | O2: jun | P2: jul | Q2: ago | R2: sep | S2: oct | T2: nov | U2: dic | V2: Total general
I3: DCO | J3: 206690743 | K3: 512465962 | L3: 555906372 | M3: 323393211 | N3: 574669921 | O3: 202280197 | V3: 2375406406
I4: Total general | J4: 206690743 | K4: 512465962 | L4: 555906372 | M4: 323393211 | N4: 574669921 | O4: 202280197 | V4: 2375406406
I25: Ingreso_Salesforce | J25: Etiquetas de columna
I26: Etiquetas de fila | J26: ene | K26: feb | L26: mar | M26: abr | N26: may | O26: jun | P26: Total general
I27: DAC | J27: -169531556 | K27: 229661282 | L27: 132474079 | M27: 254268998 | N27: 4.6957042e+08 | O27: 3.6332564e+08 | P27: 1.2797689e+09
I28: DCO | J28: 842635563 | K28: 592333115 | L28: 354793861 | M28: 4.2707473e+08 | N28: 892309408 | O28: 486320169 | P28: 3.5954668e+09
I29: DDA | J29: 181228409 | K29: 129936364 | L29: 134027273 | M29: 157001893 | N29: 40429545 | O29: 130045454 | P29: 772668938
I30: DEP | J30: 27617921 | K30: 1.7119322e+08 | L30: 2.5230381e+08 | M30: 1.2067604e+08 | N30: 62156575 | O30: 79488858 | P30: 7.1343642e+08
I31: DES | J31: 289140060 | K31: 2.5750274e+08 | L31: 270815880 | M31: 267801174 | N31: 1.3945091e+08 | O31: 3.2742769e+08 | P31: 1.5521385e+09
I32: DGI | J32: 1271029488 | K32: 1406463891 | L32: 1321970041 | M32: -137844577 | N32: 3434507158 | O32: 1229933471 | P32: 8526059472
I33: DGL | J33: 286168992 | K33: 338984671 | L33: 230154271 | M33: 451087812 | N33: 341520986 | O33: 436919745 | P33: 2084836477
I34: DHC | J34: 73086361 | K34: 73231017 | L34: 80734296 | M34: 85650722 | N34: 83985839 | O34: 146170041 | P34: 542858276
I35: DHI | J35: 218731800 | K35: 172601844 | L35: 161539048 | M35: 196879192 | N35: 201803161 | O35: 125279423 | P35: 1076834468
I36: DIC | J36: 16026670 | K36: 57914174 | L36: 25901536 | M36: 90119211 | N36: 81835932 | O36: 41091978 | P36: 312889501
I37: DIO | J37: 50982594 | K37: 54985753 | L37: 42216285 | M37: 80987512 | N37: 47400975 | O37: 47567549 | P37: 324140668
I38: DPR | J38: 522514884 | K38: 478946114 | L38: 4.0956632e+08 | M38: 5.4676366e+08 | N38: 530145136 | O38: 492863760 | P38: 2980799873
I39: DTC | J39: 1.0186675e+08 | K39: 1.5340891e+08 | L39: 2.1757082e+08 | M39: 1.6916078e+08 | N39: 2.5458868e+08 | O39: 2.1220769e+08 | P39: 1.1088036e+09
I40: SDG | O40: 444000 | P40: 444000
I41: SDO | J41: 3594914 | K41: 198466 | L41: 5612144 | M41: 3876374 | N41: 3868251 | O41: 4465971 | P41: 21616120
I42: Total general | J42: 3.7150929e+09 | K42: 4.1173616e+09 | L42: 3.6396797e+09 | M42: 2.7135035e+09 | N42: 6.583573e+09 | O42: 4.1235514e+09 | P42: 2.4892762e+10
I62: Salesforce | J62: Ene | K62: Feb | L62: Mar | M62: Abr | N62: May | O62: Jun | P62: Jul | Q62: Ago | R62: Sep | S62: Oct | T62: Nov | U62: Dic | V62: Total
I63: DCO | J63: =IFERROR(VLOOKUP($I63,$I$26:$V$42,MATCH(J$62,$I$26:$V$26,0),0),0) -> 842635563 | K63: =IFERROR(VLOOKUP($I63,$I$26:$V$42,MATCH(K$62,$I$26:$V$26,0),0),0) -> 592333115 | L63: =IFERROR(VLOOKUP($I63,$I$26:$V$42,MATCH(L$62,$I$26:$V$26,0),0),0) -> 354793861 | M63: =IFERROR(VLOOKUP($I63,$I$26:$V$42,MATCH(M$62,$I$26:$V$26,0),0),0) -> 4.2707473e+08 | N63: =IFERROR(VLOOKUP($I63,$I$26:$V$42,MATCH(N$62,$I$26:$V$26,0),0),0) -> 892309408 | O63: =IFERROR(VLOOKUP($I63,$I$26:$V$42,MATCH(O$62,$I$26:$V$26,0),0),0) -> 486320169 | P63: =IFERROR(VLOOKUP($I63,$I$26:$V$42,MATCH(P$62,$I$26:$V$26,0),0),0) -> 0 | Q63: =IFERROR(VLOOKUP($I63,$I$26:$V$42,MATCH(Q$62,$I$26:$V$26,0),0),0) -> 0 | ... U63: =IFERROR(VLOOKUP($I63,$I$26:$V$42,MATCH(U$62,$I$26:$V$26,0),0),0) -> 0 | V63: =SUM(J63:U63) -> 3.5954668e+09
I83: Diferencia | J83: Ene | K83: Feb | L83: Mar | M83: Abr | N83: May | O83: Jun | P83: Jul | Q83: Ago | R83: Sep | S83: Oct | T83: Nov | U83: Dic | V83: Total
I84: DCO | J84: =-IFERROR(VLOOKUP($I84,$I$62:$U$80,MATCH(J$83,$I$62:$U$62,0),0),0)+IFERROR(VLOOKUP($I84,$I$2:$U$23,MATCH(J$83,$I$2:$U$2,0),0),0) -> -635944820 | K84: =-IFERROR(VLOOKUP($I84,$I$62:$U$80,MATCH(K$83,$I$62:$U$62,0),0),0)+IFERROR(VLOOKUP($I84,$I$2:$U$23,MATCH(K$83,$I$2:$U$2,0),0),0) -> -79867153 | L84: =-IFERROR(VLOOKUP($I84,$I$62:$U$80,MATCH(L$83,$I$62:$U$62,0),0),0)+IFERROR(VLOOKUP($I84,$I$2:$U$23,MATCH(L$83,$I$2:$U$2,0),0),0) -> 201112511 | M84: =-IFERROR(VLOOKUP($I84,$I$62:$U$80,MATCH(M$83,$I$62:$U$62,0),0),0)+IFERROR(VLOOKUP($I84,$I$2:$U$23,MATCH(M$83,$I$2:$U$2,0),0),0) -> -1.0368152e+08 | N84: =-IFERROR(VLOOKUP($I84,$I$62:$U$80,MATCH(N$83,$I$62:$U$62,0),0),0)+IFERROR(VLOOKUP($I84,$I$2:$U$23,MATCH(N$83,$I$2:$U$2,0),0),0) -> -317639487 | O84: =-IFERROR(VLOOKUP($I84,$I$62:$U$80,MATCH(O$83,$I$62:$U$62,0),0),0)+IFERROR(VLOOKUP($I84,$I$2:$U$23,MATCH(O$83,$I$2:$U$2,0),0),0) -> -284039972 | P84: =-IFERROR(VLOOKUP($I84,$I$62:$U$80,MATCH(P$83,$I$62:$U$62,0),0),0)+IFERROR(VLOOKUP($I84,$I$2:$U$23,MATCH(P$83,$I$2:$U$2,0),0),0) -> 0 | Q84: =-IFERROR(VLOOKUP($I84,$I$62:$U$80,MATCH(Q$83,$I$62:$U$62,0),0),0)+IFERROR(VLOOKUP($I84,$I$2:$U$23,MATCH(Q$83,$I$2:$U$2,0),0),0) -> 0 | ... U84: =-IFERROR(VLOOKUP($I84,$I$62:$U$80,MATCH(U$83,$I$62:$U$62,0),0),0)+IFERROR(VLOOKUP($I84,$I$2:$U$23,MATCH(U$83,$I$2:$U$2,0),0),0) -> 0 | V84: =SUM(J84:U84) -> -1.2200604e+09
I86: siglaDivision | J86: DCO | Z86: División | AA86: DCO
I88: EERR s/TI Fact | L88: fecha (mes) | Z88: Ingreso_Salesforce | AA88: Etiquetas de columna
A89: Facturación: Incluye Facturación externa y Traspasos de Servicios Internos | I89: Clasificación | J89: cuenta_contable_full | K89: Referencia Interna | L89: ene | M89: feb | N89: mar | O89: abr | P89: may | Q89: jun | R89: Total general | Z89: Etiquetas de fila | AA89: ene | AB89: feb | AC89: mar | AD89: abr | AE89: may | AF89: jun | AG89: Total general
A90: Traspasos: Corresponde solo a Traspasos de Facturación | I90: Ingresos | J90: 61010323 Análisis de materiales | L90: 3974932 | M90: 1641121 | O90: 1578203 | Q90: 119602 | R90: 7313858 | Z90: OP-DHC-2022-0093 - VTA (+01) Enero 2026 | AA90: 121616 | AG90: 121616
A91: Valor en círculo: Representa diferncia entre Backlog y Facturación | I91: Ingresos | J91: 61010323 Análisis de materiales | K91: OP-DHC-2022-0093 - VTA (+01) Enero 2026 | L91: 121616 | M91: -121616 | R91: 0 | Z91: OPR.DCO.2024-0948 - Licitación Codelco Andina | AE91: 102940866 | AF91: 37000000 | AG91: 139940866
I92: Ingresos | J92: 61010323 Análisis de materiales | K92: OPR.DCO.2025-0091 Licitación Codelco Chuqui Contramuestras | L92: 9789343 | N92: 897033 | R92: 10686376 | Z92: OPR.DCO.2025-0091 Licitación Codelco Chuqui Contramuestras | AD92: 62063028 | AG92: 62063028
I93: Ingresos | J93: 61010323 Análisis de materiales | K93: PR.DCO.1776.2023.104_Visitas_Permanencias_Aeropuerto | L93: 5742478 | R93: 5742478 | Z93: PR.DCO.1776.2023.104_Visitas_Permanencias_Aeropuerto | AB93: 76214541 | AG93: 76214541
I94: Ingresos | J94: 61010323 Análisis de materiales | K94: PR.DCO.1776.2024.177_INGEVEC-Ppal Cap. Ign. Carrera Pinto, Conchalí Adicional (+Vta Agosto) | L94: 399682 | R94: 399682 | Z94: PR.DCO.1776.2024.131_OHL-Mejoramiento Jenainpol Ñuñoa | AA94: 2785097 | AG94: 2785097
I95: Ingresos | J95: 61010323 Análisis de materiales | K95: PR.DCO.1776.2024.212 Cesfam Padre Hurtado | L95: 905797 | M95: 810004 | O95: 3575327 | P95: 859910 | Q95: 280214 | R95: 6431252 | Z95: PR.DCO.1776.2024.212 Cesfam Padre Hurtado | AA95: 10000000 | AC95: 13501393 | AG95: 23501393
I96: Ingresos | J96: 61010323 Análisis de materiales | K96: PR.DCO.1776.2024.317 Icafal Edificio Santa Rosa H47 | M96: 79195 | R96: 79195 | Z96: PR.DCO.1776.2024.220_BESALCO CONSTRUCCIONES-Placas de Carga | AA96: 6120060 | AG96: 6120060
I97: Ingresos | J97: 61010323 Análisis de materiales | K97: PR.DCO.1776.2024.345_VDZ-San Pablo Barracas | O97: 310765 | P97: -310765 | Q97: 310765 | R97: 310765 | Z97: PR.DCO.1776.2024.316_NOVATEC EDIF.-Barón de Juras Reales | AA97: 907332 | AG97: 907332
I98: Ingresos | J98: 61010323 Análisis de materiales | K98: PR.DCO.1776.2024.351_José M. Carreño_San Francisco | N98: 525236 | O98: 1075726 | P98: 300902 | Q98: 319606 | R98: 2221470 | Z98: PR.DCO.1776.2024.379_PL EDIFICACIONES-Distrito Paulista | AA98: 949102 | AG98: 949102
I99: Ingresos | J99: 61010323 Análisis de materiales | K99: PR.DCO.1776.2024.351_José M. Carreño-T. Tannenbaum | L99: 190694 | P99: 601803 | Q99: 146198 | R99: 938695 | Z99: PR.DCO.1776.2025.028_DPC-Data Center Etapa 2 | AF99: 1500000 | AG99: 1500000
I100: Ingresos | J100: 61010323 Análisis de materiales | K100: PR.DCO.1776.2024.374_INGEC-Rengo Adicional | L100: 15179012 | O100: 3760271 | R100: 18939283 | Z100: PR.DCO.1776.2025.076_Ferroactiva-F-139 Padre Hurtado | AA100: 19493 | AG100: 19493
...

Sheet DDA
I1: EERR s/TI Fact | J1: Etiquetas de columna
